<?xml version="1.0" encoding="utf-8"?>
<!-- =================================================================================== -->
<!-- |    This document was autogenerated by xacro from robot.xacro                    | -->
<!-- |    EDITING THIS FILE BY HAND IS NOT RECOMMENDED                                 | -->
<!-- =================================================================================== -->
  <!-- | 
    <material name="yellow"
	    <color rgba="1 0.4 0 1"/>
    </material>
    <material name="black">
    	<color rgba="0 0 0 0.95"/>
    </material>
    <material name="grew">
        <color rgba="0.75 0.75 0.75 1"/>
    </material>
| -->
<robot name="robot" >

  <link name="base_link">
    <visual>
      <origin rpy="0 0 0" xyz="0 0 0.05"/>
      <geometry>
                <box size="1.0 1.0 0.1"/>
      </geometry>
    </visual>
    <collision>
      <origin rpy="0 0 0" xyz="0 0 0.04"/>
      <geometry>
                <box size="1.0 1.0 0.1"/>
      </geometry>
    </collision>

    <inertial>
      <origin rpy="0 0 0" xyz="0 0 0.04"/>
      <mass value="636.134233847578"/>
      <inertia ixx="1639.81286905023" ixy="-36.6455977200006" ixz="-0.782493840000301" iyy="1639.91375187705" iyz="-5.77195100431517" izz="3261.44630486213"/>
    </inertial>
  </link>


  <joint name="yawl_joint" type="continuous">
    <origin rpy="0 0 0" xyz="0 0 0.1"/>
    <parent link="base_link"/>
    <child link="yawl_link"/>
    <axis xyz="0 0 1"/>
  </joint>

  <link name="yawl_link">
    
    <inertial>
      <origin rpy="0 0 0" xyz="0 0 0.04"/>
      <mass value="636.134233847578"/>
      <inertia ixx="1639.81286905023" ixy="-36.6455977200006" ixz="-0.782493840000301" iyy="1639.91375187705" iyz="-5.77195100431517" izz="3261.44630486213"/>
    </inertial>
    <visual>
      <origin rpy="0 0 0" xyz="0 0 0.005"/>
      <geometry>
                       <box size="0.05 0.05 0.01"/>
      </geometry>
    </visual>
    <collision>
      <origin rpy="0 0 0" xyz="0 0 0.004"/>
      <geometry>
        <box size="0.05 0.05 0.01"/>
      </geometry>
    </collision>
  </link>

  <joint name="pitch_joint11" type="continuous">
    <origin rpy="0 0 0" xyz="0 0 0.005"/>
    <parent link="yawl_link"/>
    <child link="pitch_link1"/>
    <axis xyz="1 0 0"/>
  </joint>

  <link name="pitch_link1">

    <inertial>
      <origin rpy="0 0 0" xyz="0 0 0.04"/>
      <mass value="636.134233847578"/>
      <inertia ixx="1639.81286905023" ixy="-36.6455977200006" ixz="-0.782493840000301" iyy="1639.91375187705" iyz="-5.77195100431517" izz="3261.44630486213"/>
    </inertial>
    <visual>
      <origin rpy="0 0 0" xyz="0 0 0.25"/>
      <geometry>
        <box size="0.05 0.05 0.5"/>
      </geometry>
    </visual>
    <collision>
      <origin rpy="0 0 0" xyz="0 0 0.20"/>
      <geometry>
        <box size="0.05 0.05 0.5"/>
      </geometry>
    </collision>
  </link>

  <link name="pitch_link2">
    <!--<cylinder_inertial_matrix m="1" r="0.05" h="0.2"/>-->
    <inertial>
      <origin rpy="0 0 0" xyz="0 0 0.04"/>
      <mass value="636.134233847578"/>
      <inertia ixx="1639.81286905023" ixy="-36.6455977200006" ixz="-0.782493840000301" iyy="1639.91375187705" iyz="-5.77195100431517" izz="3261.44630486213"/>
    </inertial>
    <visual>
      <origin rpy="0 0 0" xyz="0 0 0.1"/>
      <geometry>
        <box size="0.05 0.05 0.2"/>
      </geometry>
    </visual>
    <collision>
      <origin rpy="0 0 0" xyz="0 0 0.07"/>
      <geometry>
        <box size="0.05 0.05 0.2"/>
      </geometry>
    </collision>
  </link>

  <joint name="pitch_joint2" type="continuous">
    <origin rpy="0 0 0" xyz="0 0 0.5"/>
    <parent link="pitch_link1"/>
    <child link="pitch_link2"/>
    <axis xyz="1 0 0"/>
  </joint>

</robot>